[2022-07-29T09:58:53] WARNING [django.request.log_response:224] Not Found: /favicon.ico
[2022-07-29T09:59:01] INFO [root.showapps:42] hp_seen the whole applist
[2022-07-29T09:59:04] WARNING [django.request.log_response:224] Not Found: /apps/whatsapp/dashboard/assets/css/styles.css
[2022-07-29T09:59:05] WARNING [django.request.log_response:224] Not Found: /apps/whatsapp/dashboard/assets/img/illustrations/rocket-white.png
[2022-07-29T09:59:05] WARNING [django.request.log_response:224] Not Found: /apps/whatsapp/dashboard/assets/css/styles.css
[2022-07-29T09:59:05] WARNING [django.request.log_response:224] Not Found: /apps/whatsapp/dashboard/assets/img/small-logos/logo-xd.svg
[2022-07-29T09:59:05] WARNING [django.request.log_response:224] Not Found: /apps/whatsapp/dashboard/assets/img/team-1.jpg
[2022-07-29T09:59:05] WARNING [django.request.log_response:224] Not Found: /apps/whatsapp/dashboard/assets/img/team-4.jpg
[2022-07-29T09:59:05] WARNING [django.request.log_response:224] Not Found: /apps/whatsapp/dashboard/assets/img/team-2.jpg
[2022-07-29T09:59:05] WARNING [django.request.log_response:224] Not Found: /apps/whatsapp/dashboard/assets/img/team-3.jpg
[2022-07-29T09:59:05] WARNING [django.request.log_response:224] Not Found: /apps/whatsapp/dashboard/assets/img/small-logos/logo-atlassian.svg
[2022-07-29T09:59:05] WARNING [django.request.log_response:224] Not Found: /apps/whatsapp/dashboard/assets/img/small-logos/logo-slack.svg
[2022-07-29T09:59:05] WARNING [django.request.log_response:224] Not Found: /apps/whatsapp/dashboard/assets/img/small-logos/logo-spotify.svg
[2022-07-29T09:59:05] WARNING [django.request.log_response:224] Not Found: /apps/whatsapp/dashboard/assets/img/small-logos/logo-jira.svg
[2022-07-29T09:59:05] WARNING [django.request.log_response:224] Not Found: /apps/whatsapp/dashboard/assets/img/small-logos/logo-invision.svg
[2022-07-29T09:59:05] WARNING [django.request.log_response:224] Not Found: /apps/whatsapp/dashboard/assets/js/plugins/chartjs.min.js
[2022-07-29T09:59:05] WARNING [django.request.log_response:224] Not Found: /apps/whatsapp/dashboard/assets/js/plugins/perfect-scrollbar.min.js
[2022-07-29T09:59:05] WARNING [django.request.log_response:224] Not Found: /apps/whatsapp/dashboard/assets/img/team-1.jpg
[2022-07-29T09:59:05] WARNING [django.request.log_response:224] Not Found: /apps/whatsapp/dashboard/assets/img/ivancik.jpg
[2022-07-29T09:59:09] WARNING [django.request.log_response:224] Not Found: /apps/whatsapp/dashboard/bulk.html
[2022-07-29T09:59:17] WARNING [django.request.log_response:224] Not Found: /hp/js/create.js
[2022-07-29T09:59:56] WARNING [django.request.log_response:224] Not Found: /hp/js/create.js
[2022-07-29T10:27:57] INFO [django.utils.autoreload.trigger_reload:251] C:\Users\hp\Desktop\Internship Assignments\billapp\apps\views.py changed, reloading.
[2022-07-29T10:27:57] DEBUG [asyncio.__init__:624] Using proactor: IocpProactor
[2022-07-29T10:27:58] DEBUG [asyncio.__init__:624] Using proactor: IocpProactor
[2022-07-29T10:28:18] INFO [django.utils.autoreload.trigger_reload:251] C:\Users\hp\Desktop\Internship Assignments\billapp\apps\views.py changed, reloading.
[2022-07-29T10:28:20] DEBUG [asyncio.__init__:624] Using proactor: IocpProactor
[2022-07-29T10:28:37] INFO [django.utils.autoreload.trigger_reload:251] C:\Users\hp\Desktop\Internship Assignments\billapp\apps\views.py changed, reloading.
[2022-07-29T10:28:39] DEBUG [asyncio.__init__:624] Using proactor: IocpProactor
[2022-07-29T10:28:51] INFO [django.utils.autoreload.trigger_reload:251] C:\Users\hp\Desktop\Internship Assignments\billapp\apps\views.py changed, reloading.
[2022-07-29T10:28:52] DEBUG [asyncio.__init__:624] Using proactor: IocpProactor
[2022-07-29T10:39:16] INFO [django.utils.autoreload.trigger_reload:251] C:\Users\hp\Desktop\Internship Assignments\billapp\apps\urls.py changed, reloading.
[2022-07-29T10:39:17] DEBUG [asyncio.__init__:624] Using proactor: IocpProactor
[2022-07-29T10:40:11] ERROR [django.request.log_response:224] Internal Server Error: /hp/whatsapp
Traceback (most recent call last):
  File "C:\Users\hp\AppData\Local\Packages\PythonSoftwareFoundation.Python.3.9_qbz5n2kfra8p0\LocalCache\local-packages\Python39\site-packages\django\core\handlers\exception.py", line 47, in inner
    response = get_response(request)
  File "C:\Users\hp\AppData\Local\Packages\PythonSoftwareFoundation.Python.3.9_qbz5n2kfra8p0\LocalCache\local-packages\Python39\site-packages\django\core\handlers\base.py", line 204, in _get_response
    response = response.render()
  File "C:\Users\hp\AppData\Local\Packages\PythonSoftwareFoundation.Python.3.9_qbz5n2kfra8p0\LocalCache\local-packages\Python39\site-packages\django\template\response.py", line 105, in render
    self.content = self.rendered_content
  File "C:\Users\hp\AppData\Local\Packages\PythonSoftwareFoundation.Python.3.9_qbz5n2kfra8p0\LocalCache\local-packages\Python39\site-packages\django\template\response.py", line 83, in rendered_content
    return template.render(context, self._request)
  File "C:\Users\hp\AppData\Local\Packages\PythonSoftwareFoundation.Python.3.9_qbz5n2kfra8p0\LocalCache\local-packages\Python39\site-packages\django\template\backends\django.py", line 61, in render
    return self.template.render(context)
  File "C:\Users\hp\AppData\Local\Packages\PythonSoftwareFoundation.Python.3.9_qbz5n2kfra8p0\LocalCache\local-packages\Python39\site-packages\django\template\base.py", line 170, in render
    return self._render(context)
  File "C:\Users\hp\AppData\Local\Packages\PythonSoftwareFoundation.Python.3.9_qbz5n2kfra8p0\LocalCache\local-packages\Python39\site-packages\django\template\base.py", line 162, in _render
    return self.nodelist.render(context)
  File "C:\Users\hp\AppData\Local\Packages\PythonSoftwareFoundation.Python.3.9_qbz5n2kfra8p0\LocalCache\local-packages\Python39\site-packages\django\template\base.py", line 938, in render
    bit = node.render_annotated(context)
  File "C:\Users\hp\AppData\Local\Packages\PythonSoftwareFoundation.Python.3.9_qbz5n2kfra8p0\LocalCache\local-packages\Python39\site-packages\django\template\base.py", line 905, in render_annotated
    return self.render(context)
  File "C:\Users\hp\AppData\Local\Packages\PythonSoftwareFoundation.Python.3.9_qbz5n2kfra8p0\LocalCache\local-packages\Python39\site-packages\django\template\defaulttags.py", line 446, in render
    url = reverse(view_name, args=args, kwargs=kwargs, current_app=current_app)
  File "C:\Users\hp\AppData\Local\Packages\PythonSoftwareFoundation.Python.3.9_qbz5n2kfra8p0\LocalCache\local-packages\Python39\site-packages\django\urls\base.py", line 86, in reverse
    return resolver._reverse_with_prefix(view, prefix, *args, **kwargs)
  File "C:\Users\hp\AppData\Local\Packages\PythonSoftwareFoundation.Python.3.9_qbz5n2kfra8p0\LocalCache\local-packages\Python39\site-packages\django\urls\resolvers.py", line 694, in _reverse_with_prefix
    raise NoReverseMatch(msg)
django.urls.exceptions.NoReverseMatch: Reverse for 'update-app' with arguments '('',)' not found. 1 pattern(s) tried: ['apps/(?P<appslug>[^/]+)/settings$']
[2022-07-29T10:40:39] WARNING [django.request.log_response:224] Not Found: /hp/js/create.js
[2022-07-29T10:40:46] ERROR [django.request.log_response:224] Internal Server Error: /apps/whatsapp/settings
Traceback (most recent call last):
  File "C:\Users\hp\AppData\Local\Packages\PythonSoftwareFoundation.Python.3.9_qbz5n2kfra8p0\LocalCache\local-packages\Python39\site-packages\django\core\handlers\exception.py", line 47, in inner
    response = get_response(request)
  File "C:\Users\hp\AppData\Local\Packages\PythonSoftwareFoundation.Python.3.9_qbz5n2kfra8p0\LocalCache\local-packages\Python39\site-packages\django\core\handlers\base.py", line 181, in _get_response
    response = wrapped_callback(request, *callback_args, **callback_kwargs)
  File "C:\Users\hp\Desktop\Internship Assignments\billapp\apps\views.py", line 67, in update_app
    'form': AppForm(instance=app),
TypeError: __init__() got an unexpected keyword argument 'instance'
[2022-07-29T10:41:14] INFO [django.utils.autoreload.trigger_reload:251] C:\Users\hp\Desktop\Internship Assignments\billapp\apps\forms.py changed, reloading.
[2022-07-29T10:41:20] WARNING [django.request.log_response:224] Not Found: /hp/js/create.js
[2022-07-29T10:41:22] ERROR [django.request.log_response:224] Internal Server Error: /apps/whatsapp/settings
Traceback (most recent call last):
  File "C:\Users\hp\AppData\Local\Packages\PythonSoftwareFoundation.Python.3.9_qbz5n2kfra8p0\LocalCache\local-packages\Python39\site-packages\django\core\handlers\exception.py", line 47, in inner
    response = get_response(request)
  File "C:\Users\hp\AppData\Local\Packages\PythonSoftwareFoundation.Python.3.9_qbz5n2kfra8p0\LocalCache\local-packages\Python39\site-packages\django\core\handlers\base.py", line 181, in _get_response
    response = wrapped_callback(request, *callback_args, **callback_kwargs)
  File "C:\Users\hp\Desktop\Internship Assignments\billapp\apps\views.py", line 67, in update_app
    'form': AppForm(instance=app),
TypeError: __init__() got an unexpected keyword argument 'instance'
[2022-07-29T10:41:37] INFO [django.utils.autoreload.trigger_reload:251] C:\Users\hp\Desktop\Internship Assignments\billapp\apps\forms.py changed, reloading.
[2022-07-29T10:41:37] DEBUG [asyncio.__init__:624] Using proactor: IocpProactor
[2022-07-29T10:41:38] DEBUG [asyncio.__init__:624] Using proactor: IocpProactor
[2022-07-29T10:49:04] INFO [django.utils.autoreload.trigger_reload:251] C:\Users\hp\Desktop\Internship Assignments\billapp\apps\views.py changed, reloading.
[2022-07-29T10:49:05] DEBUG [asyncio.__init__:624] Using proactor: IocpProactor
[2022-07-29T10:49:42] INFO [django.utils.autoreload.trigger_reload:251] C:\Users\hp\Desktop\Internship Assignments\billapp\apps\views.py changed, reloading.
[2022-07-29T10:49:43] DEBUG [asyncio.__init__:624] Using proactor: IocpProactor
[2022-07-29T10:50:10] ERROR [django.request.log_response:224] Internal Server Error: /apps/whatsapp/settings
Traceback (most recent call last):
  File "C:\Users\hp\AppData\Local\Packages\PythonSoftwareFoundation.Python.3.9_qbz5n2kfra8p0\LocalCache\local-packages\Python39\site-packages\django\core\handlers\exception.py", line 47, in inner
    response = get_response(request)
  File "C:\Users\hp\AppData\Local\Packages\PythonSoftwareFoundation.Python.3.9_qbz5n2kfra8p0\LocalCache\local-packages\Python39\site-packages\django\core\handlers\base.py", line 181, in _get_response
    response = wrapped_callback(request, *callback_args, **callback_kwargs)
  File "C:\Users\hp\Desktop\Internship Assignments\billapp\apps\views.py", line 74, in update_app
    return render(request, 'app_settings.html', payload)
  File "C:\Users\hp\AppData\Local\Packages\PythonSoftwareFoundation.Python.3.9_qbz5n2kfra8p0\LocalCache\local-packages\Python39\site-packages\django\shortcuts.py", line 19, in render
    content = loader.render_to_string(template_name, context, request, using=using)
  File "C:\Users\hp\AppData\Local\Packages\PythonSoftwareFoundation.Python.3.9_qbz5n2kfra8p0\LocalCache\local-packages\Python39\site-packages\django\template\loader.py", line 62, in render_to_string
    return template.render(context, request)
  File "C:\Users\hp\AppData\Local\Packages\PythonSoftwareFoundation.Python.3.9_qbz5n2kfra8p0\LocalCache\local-packages\Python39\site-packages\django\template\backends\django.py", line 61, in render
    return self.template.render(context)
  File "C:\Users\hp\AppData\Local\Packages\PythonSoftwareFoundation.Python.3.9_qbz5n2kfra8p0\LocalCache\local-packages\Python39\site-packages\django\template\base.py", line 170, in render
    return self._render(context)
  File "C:\Users\hp\AppData\Local\Packages\PythonSoftwareFoundation.Python.3.9_qbz5n2kfra8p0\LocalCache\local-packages\Python39\site-packages\django\template\base.py", line 162, in _render
    return self.nodelist.render(context)
  File "C:\Users\hp\AppData\Local\Packages\PythonSoftwareFoundation.Python.3.9_qbz5n2kfra8p0\LocalCache\local-packages\Python39\site-packages\django\template\base.py", line 938, in render
    bit = node.render_annotated(context)
  File "C:\Users\hp\AppData\Local\Packages\PythonSoftwareFoundation.Python.3.9_qbz5n2kfra8p0\LocalCache\local-packages\Python39\site-packages\django\template\base.py", line 905, in render_annotated
    return self.render(context)
  File "C:\Users\hp\AppData\Local\Packages\PythonSoftwareFoundation.Python.3.9_qbz5n2kfra8p0\LocalCache\local-packages\Python39\site-packages\django\template\loader_tags.py", line 53, in render
    result = self.nodelist.render(context)
  File "C:\Users\hp\AppData\Local\Packages\PythonSoftwareFoundation.Python.3.9_qbz5n2kfra8p0\LocalCache\local-packages\Python39\site-packages\django\template\base.py", line 938, in render
    bit = node.render_annotated(context)
  File "C:\Users\hp\AppData\Local\Packages\PythonSoftwareFoundation.Python.3.9_qbz5n2kfra8p0\LocalCache\local-packages\Python39\site-packages\django\template\base.py", line 905, in render_annotated
    return self.render(context)
  File "C:\Users\hp\AppData\Local\Packages\PythonSoftwareFoundation.Python.3.9_qbz5n2kfra8p0\LocalCache\local-packages\Python39\site-packages\django\template\defaulttags.py", line 446, in render
    url = reverse(view_name, args=args, kwargs=kwargs, current_app=current_app)
  File "C:\Users\hp\AppData\Local\Packages\PythonSoftwareFoundation.Python.3.9_qbz5n2kfra8p0\LocalCache\local-packages\Python39\site-packages\django\urls\base.py", line 86, in reverse
    return resolver._reverse_with_prefix(view, prefix, *args, **kwargs)
  File "C:\Users\hp\AppData\Local\Packages\PythonSoftwareFoundation.Python.3.9_qbz5n2kfra8p0\LocalCache\local-packages\Python39\site-packages\django\urls\resolvers.py", line 694, in _reverse_with_prefix
    raise NoReverseMatch(msg)
django.urls.exceptions.NoReverseMatch: Reverse for 'update-app' with arguments '('',)' not found. 1 pattern(s) tried: ['apps/(?P<appslug>[^/]+)/settings$']
[2022-07-29T10:50:31] ERROR [django.request.log_response:224] Internal Server Error: /apps/whatsapp/settings
Traceback (most recent call last):
  File "C:\Users\hp\AppData\Local\Packages\PythonSoftwareFoundation.Python.3.9_qbz5n2kfra8p0\LocalCache\local-packages\Python39\site-packages\django\core\handlers\exception.py", line 47, in inner
    response = get_response(request)
  File "C:\Users\hp\AppData\Local\Packages\PythonSoftwareFoundation.Python.3.9_qbz5n2kfra8p0\LocalCache\local-packages\Python39\site-packages\django\core\handlers\base.py", line 181, in _get_response
    response = wrapped_callback(request, *callback_args, **callback_kwargs)
  File "C:\Users\hp\Desktop\Internship Assignments\billapp\apps\views.py", line 66, in update_app
    app.author = Profile.objects.get(user__id=form.cleaned_data.get('author'))
  File "C:\Users\hp\AppData\Local\Packages\PythonSoftwareFoundation.Python.3.9_qbz5n2kfra8p0\LocalCache\local-packages\Python39\site-packages\django\db\models\fields\related_descriptors.py", line 215, in __set__
    raise ValueError(
ValueError: Cannot assign "<Profile: hp>": "applists.author" must be a "User" instance.
[2022-07-29T10:50:59] INFO [django.utils.autoreload.trigger_reload:251] C:\Users\hp\Desktop\Internship Assignments\billapp\apps\views.py changed, reloading.
[2022-07-29T10:51:01] DEBUG [asyncio.__init__:624] Using proactor: IocpProactor
[2022-07-29T10:51:08] ERROR [django.request.log_response:224] Internal Server Error: /apps/whatsapp/settings
Traceback (most recent call last):
  File "C:\Users\hp\AppData\Local\Packages\PythonSoftwareFoundation.Python.3.9_qbz5n2kfra8p0\LocalCache\local-packages\Python39\site-packages\django\db\backends\utils.py", line 84, in _execute
    return self.cursor.execute(sql, params)
  File "C:\Users\hp\AppData\Local\Packages\PythonSoftwareFoundation.Python.3.9_qbz5n2kfra8p0\LocalCache\local-packages\Python39\site-packages\django\db\backends\sqlite3\base.py", line 423, in execute
    return Database.Cursor.execute(self, query, params)
sqlite3.IntegrityError: UNIQUE constraint failed: apps_applists.slug

The above exception was the direct cause of the following exception:

Traceback (most recent call last):
  File "C:\Users\hp\AppData\Local\Packages\PythonSoftwareFoundation.Python.3.9_qbz5n2kfra8p0\LocalCache\local-packages\Python39\site-packages\django\core\handlers\exception.py", line 47, in inner
    response = get_response(request)
  File "C:\Users\hp\AppData\Local\Packages\PythonSoftwareFoundation.Python.3.9_qbz5n2kfra8p0\LocalCache\local-packages\Python39\site-packages\django\core\handlers\base.py", line 181, in _get_response
    response = wrapped_callback(request, *callback_args, **callback_kwargs)
  File "C:\Users\hp\Desktop\Internship Assignments\billapp\apps\views.py", line 67, in update_app
    app.save(update_fields=['author'])
  File "C:\Users\hp\Desktop\Internship Assignments\billapp\apps\models.py", line 33, in save
    super(applists, self).save()
  File "C:\Users\hp\AppData\Local\Packages\PythonSoftwareFoundation.Python.3.9_qbz5n2kfra8p0\LocalCache\local-packages\Python39\site-packages\django\db\models\base.py", line 726, in save
    self.save_base(using=using, force_insert=force_insert,
  File "C:\Users\hp\AppData\Local\Packages\PythonSoftwareFoundation.Python.3.9_qbz5n2kfra8p0\LocalCache\local-packages\Python39\site-packages\django\db\models\base.py", line 763, in save_base
    updated = self._save_table(
  File "C:\Users\hp\AppData\Local\Packages\PythonSoftwareFoundation.Python.3.9_qbz5n2kfra8p0\LocalCache\local-packages\Python39\site-packages\django\db\models\base.py", line 868, in _save_table
    results = self._do_insert(cls._base_manager, using, fields, returning_fields, raw)
  File "C:\Users\hp\AppData\Local\Packages\PythonSoftwareFoundation.Python.3.9_qbz5n2kfra8p0\LocalCache\local-packages\Python39\site-packages\django\db\models\base.py", line 906, in _do_insert
    return manager._insert(
  File "C:\Users\hp\AppData\Local\Packages\PythonSoftwareFoundation.Python.3.9_qbz5n2kfra8p0\LocalCache\local-packages\Python39\site-packages\django\db\models\manager.py", line 85, in manager_method
    return getattr(self.get_queryset(), name)(*args, **kwargs)
  File "C:\Users\hp\AppData\Local\Packages\PythonSoftwareFoundation.Python.3.9_qbz5n2kfra8p0\LocalCache\local-packages\Python39\site-packages\django\db\models\query.py", line 1270, in _insert
    return query.get_compiler(using=using).execute_sql(returning_fields)
  File "C:\Users\hp\AppData\Local\Packages\PythonSoftwareFoundation.Python.3.9_qbz5n2kfra8p0\LocalCache\local-packages\Python39\site-packages\django\db\models\sql\compiler.py", line 1416, in execute_sql
    cursor.execute(sql, params)
  File "C:\Users\hp\AppData\Local\Packages\PythonSoftwareFoundation.Python.3.9_qbz5n2kfra8p0\LocalCache\local-packages\Python39\site-packages\django\db\backends\utils.py", line 98, in execute
    return super().execute(sql, params)
  File "C:\Users\hp\AppData\Local\Packages\PythonSoftwareFoundation.Python.3.9_qbz5n2kfra8p0\LocalCache\local-packages\Python39\site-packages\django\db\backends\utils.py", line 66, in execute
    return self._execute_with_wrappers(sql, params, many=False, executor=self._execute)
  File "C:\Users\hp\AppData\Local\Packages\PythonSoftwareFoundation.Python.3.9_qbz5n2kfra8p0\LocalCache\local-packages\Python39\site-packages\django\db\backends\utils.py", line 75, in _execute_with_wrappers
    return executor(sql, params, many, context)
  File "C:\Users\hp\AppData\Local\Packages\PythonSoftwareFoundation.Python.3.9_qbz5n2kfra8p0\LocalCache\local-packages\Python39\site-packages\django\db\backends\utils.py", line 84, in _execute
    return self.cursor.execute(sql, params)
  File "C:\Users\hp\AppData\Local\Packages\PythonSoftwareFoundation.Python.3.9_qbz5n2kfra8p0\LocalCache\local-packages\Python39\site-packages\django\db\utils.py", line 90, in __exit__
    raise dj_exc_value.with_traceback(traceback) from exc_value
  File "C:\Users\hp\AppData\Local\Packages\PythonSoftwareFoundation.Python.3.9_qbz5n2kfra8p0\LocalCache\local-packages\Python39\site-packages\django\db\backends\utils.py", line 84, in _execute
    return self.cursor.execute(sql, params)
  File "C:\Users\hp\AppData\Local\Packages\PythonSoftwareFoundation.Python.3.9_qbz5n2kfra8p0\LocalCache\local-packages\Python39\site-packages\django\db\backends\sqlite3\base.py", line 423, in execute
    return Database.Cursor.execute(self, query, params)
django.db.utils.IntegrityError: UNIQUE constraint failed: apps_applists.slug
[2022-07-29T10:52:05] INFO [django.utils.autoreload.trigger_reload:251] C:\Users\hp\Desktop\Internship Assignments\billapp\apps\views.py changed, reloading.
[2022-07-29T10:52:06] DEBUG [asyncio.__init__:624] Using proactor: IocpProactor
[2022-07-29T10:52:30] ERROR [django.request.log_response:224] Internal Server Error: /apps/whatsapp/settings
Traceback (most recent call last):
  File "C:\Users\hp\AppData\Local\Packages\PythonSoftwareFoundation.Python.3.9_qbz5n2kfra8p0\LocalCache\local-packages\Python39\site-packages\django\db\backends\utils.py", line 84, in _execute
    return self.cursor.execute(sql, params)
  File "C:\Users\hp\AppData\Local\Packages\PythonSoftwareFoundation.Python.3.9_qbz5n2kfra8p0\LocalCache\local-packages\Python39\site-packages\django\db\backends\sqlite3\base.py", line 423, in execute
    return Database.Cursor.execute(self, query, params)
sqlite3.IntegrityError: UNIQUE constraint failed: apps_applists.slug

The above exception was the direct cause of the following exception:

Traceback (most recent call last):
  File "C:\Users\hp\AppData\Local\Packages\PythonSoftwareFoundation.Python.3.9_qbz5n2kfra8p0\LocalCache\local-packages\Python39\site-packages\django\core\handlers\exception.py", line 47, in inner
    response = get_response(request)
  File "C:\Users\hp\AppData\Local\Packages\PythonSoftwareFoundation.Python.3.9_qbz5n2kfra8p0\LocalCache\local-packages\Python39\site-packages\django\core\handlers\base.py", line 181, in _get_response
    response = wrapped_callback(request, *callback_args, **callback_kwargs)
  File "C:\Users\hp\Desktop\Internship Assignments\billapp\apps\views.py", line 65, in update_app
    app = form.save()
  File "C:\Users\hp\AppData\Local\Packages\PythonSoftwareFoundation.Python.3.9_qbz5n2kfra8p0\LocalCache\local-packages\Python39\site-packages\django\forms\models.py", line 468, in save
    self.instance.save()
  File "C:\Users\hp\Desktop\Internship Assignments\billapp\apps\models.py", line 33, in save
    super(applists, self).save()
  File "C:\Users\hp\AppData\Local\Packages\PythonSoftwareFoundation.Python.3.9_qbz5n2kfra8p0\LocalCache\local-packages\Python39\site-packages\django\db\models\base.py", line 726, in save
    self.save_base(using=using, force_insert=force_insert,
  File "C:\Users\hp\AppData\Local\Packages\PythonSoftwareFoundation.Python.3.9_qbz5n2kfra8p0\LocalCache\local-packages\Python39\site-packages\django\db\models\base.py", line 763, in save_base
    updated = self._save_table(
  File "C:\Users\hp\AppData\Local\Packages\PythonSoftwareFoundation.Python.3.9_qbz5n2kfra8p0\LocalCache\local-packages\Python39\site-packages\django\db\models\base.py", line 868, in _save_table
    results = self._do_insert(cls._base_manager, using, fields, returning_fields, raw)
  File "C:\Users\hp\AppData\Local\Packages\PythonSoftwareFoundation.Python.3.9_qbz5n2kfra8p0\LocalCache\local-packages\Python39\site-packages\django\db\models\base.py", line 906, in _do_insert
    return manager._insert(
  File "C:\Users\hp\AppData\Local\Packages\PythonSoftwareFoundation.Python.3.9_qbz5n2kfra8p0\LocalCache\local-packages\Python39\site-packages\django\db\models\manager.py", line 85, in manager_method
    return getattr(self.get_queryset(), name)(*args, **kwargs)
  File "C:\Users\hp\AppData\Local\Packages\PythonSoftwareFoundation.Python.3.9_qbz5n2kfra8p0\LocalCache\local-packages\Python39\site-packages\django\db\models\query.py", line 1270, in _insert
    return query.get_compiler(using=using).execute_sql(returning_fields)
  File "C:\Users\hp\AppData\Local\Packages\PythonSoftwareFoundation.Python.3.9_qbz5n2kfra8p0\LocalCache\local-packages\Python39\site-packages\django\db\models\sql\compiler.py", line 1416, in execute_sql
    cursor.execute(sql, params)
  File "C:\Users\hp\AppData\Local\Packages\PythonSoftwareFoundation.Python.3.9_qbz5n2kfra8p0\LocalCache\local-packages\Python39\site-packages\django\db\backends\utils.py", line 98, in execute
    return super().execute(sql, params)
  File "C:\Users\hp\AppData\Local\Packages\PythonSoftwareFoundation.Python.3.9_qbz5n2kfra8p0\LocalCache\local-packages\Python39\site-packages\django\db\backends\utils.py", line 66, in execute
    return self._execute_with_wrappers(sql, params, many=False, executor=self._execute)
  File "C:\Users\hp\AppData\Local\Packages\PythonSoftwareFoundation.Python.3.9_qbz5n2kfra8p0\LocalCache\local-packages\Python39\site-packages\django\db\backends\utils.py", line 75, in _execute_with_wrappers
    return executor(sql, params, many, context)
  File "C:\Users\hp\AppData\Local\Packages\PythonSoftwareFoundation.Python.3.9_qbz5n2kfra8p0\LocalCache\local-packages\Python39\site-packages\django\db\backends\utils.py", line 84, in _execute
    return self.cursor.execute(sql, params)
  File "C:\Users\hp\AppData\Local\Packages\PythonSoftwareFoundation.Python.3.9_qbz5n2kfra8p0\LocalCache\local-packages\Python39\site-packages\django\db\utils.py", line 90, in __exit__
    raise dj_exc_value.with_traceback(traceback) from exc_value
  File "C:\Users\hp\AppData\Local\Packages\PythonSoftwareFoundation.Python.3.9_qbz5n2kfra8p0\LocalCache\local-packages\Python39\site-packages\django\db\backends\utils.py", line 84, in _execute
    return self.cursor.execute(sql, params)
  File "C:\Users\hp\AppData\Local\Packages\PythonSoftwareFoundation.Python.3.9_qbz5n2kfra8p0\LocalCache\local-packages\Python39\site-packages\django\db\backends\sqlite3\base.py", line 423, in execute
    return Database.Cursor.execute(self, query, params)
django.db.utils.IntegrityError: UNIQUE constraint failed: apps_applists.slug
[2022-07-29T10:53:59] INFO [django.utils.autoreload.trigger_reload:251] C:\Users\hp\Desktop\Internship Assignments\billapp\apps\views.py changed, reloading.
[2022-07-29T10:54:00] DEBUG [asyncio.__init__:624] Using proactor: IocpProactor
[2022-07-29T10:59:59] INFO [django.utils.autoreload.trigger_reload:251] C:\Users\hp\Desktop\Internship Assignments\billapp\apps\views.py changed, reloading.
[2022-07-29T11:00:00] DEBUG [asyncio.__init__:624] Using proactor: IocpProactor
[2022-07-29T11:00:18] ERROR [django.request.log_response:224] Internal Server Error: /apps/whatsapp/settings
Traceback (most recent call last):
  File "C:\Users\hp\AppData\Local\Packages\PythonSoftwareFoundation.Python.3.9_qbz5n2kfra8p0\LocalCache\local-packages\Python39\site-packages\django\db\backends\utils.py", line 84, in _execute
    return self.cursor.execute(sql, params)
  File "C:\Users\hp\AppData\Local\Packages\PythonSoftwareFoundation.Python.3.9_qbz5n2kfra8p0\LocalCache\local-packages\Python39\site-packages\django\db\backends\sqlite3\base.py", line 423, in execute
    return Database.Cursor.execute(self, query, params)
sqlite3.IntegrityError: UNIQUE constraint failed: apps_applists.slug

The above exception was the direct cause of the following exception:

Traceback (most recent call last):
  File "C:\Users\hp\AppData\Local\Packages\PythonSoftwareFoundation.Python.3.9_qbz5n2kfra8p0\LocalCache\local-packages\Python39\site-packages\django\core\handlers\exception.py", line 47, in inner
    response = get_response(request)
  File "C:\Users\hp\AppData\Local\Packages\PythonSoftwareFoundation.Python.3.9_qbz5n2kfra8p0\LocalCache\local-packages\Python39\site-packages\django\core\handlers\base.py", line 181, in _get_response
    response = wrapped_callback(request, *callback_args, **callback_kwargs)
  File "C:\Users\hp\Desktop\Internship Assignments\billapp\apps\views.py", line 65, in update_app
    print(form.save())
  File "C:\Users\hp\AppData\Local\Packages\PythonSoftwareFoundation.Python.3.9_qbz5n2kfra8p0\LocalCache\local-packages\Python39\site-packages\django\forms\models.py", line 468, in save
    self.instance.save()
  File "C:\Users\hp\Desktop\Internship Assignments\billapp\apps\models.py", line 33, in save
    super(applists, self).save()
  File "C:\Users\hp\AppData\Local\Packages\PythonSoftwareFoundation.Python.3.9_qbz5n2kfra8p0\LocalCache\local-packages\Python39\site-packages\django\db\models\base.py", line 726, in save
    self.save_base(using=using, force_insert=force_insert,
  File "C:\Users\hp\AppData\Local\Packages\PythonSoftwareFoundation.Python.3.9_qbz5n2kfra8p0\LocalCache\local-packages\Python39\site-packages\django\db\models\base.py", line 763, in save_base
    updated = self._save_table(
  File "C:\Users\hp\AppData\Local\Packages\PythonSoftwareFoundation.Python.3.9_qbz5n2kfra8p0\LocalCache\local-packages\Python39\site-packages\django\db\models\base.py", line 868, in _save_table
    results = self._do_insert(cls._base_manager, using, fields, returning_fields, raw)
  File "C:\Users\hp\AppData\Local\Packages\PythonSoftwareFoundation.Python.3.9_qbz5n2kfra8p0\LocalCache\local-packages\Python39\site-packages\django\db\models\base.py", line 906, in _do_insert
    return manager._insert(
  File "C:\Users\hp\AppData\Local\Packages\PythonSoftwareFoundation.Python.3.9_qbz5n2kfra8p0\LocalCache\local-packages\Python39\site-packages\django\db\models\manager.py", line 85, in manager_method
    return getattr(self.get_queryset(), name)(*args, **kwargs)
  File "C:\Users\hp\AppData\Local\Packages\PythonSoftwareFoundation.Python.3.9_qbz5n2kfra8p0\LocalCache\local-packages\Python39\site-packages\django\db\models\query.py", line 1270, in _insert
    return query.get_compiler(using=using).execute_sql(returning_fields)
  File "C:\Users\hp\AppData\Local\Packages\PythonSoftwareFoundation.Python.3.9_qbz5n2kfra8p0\LocalCache\local-packages\Python39\site-packages\django\db\models\sql\compiler.py", line 1416, in execute_sql
    cursor.execute(sql, params)
  File "C:\Users\hp\AppData\Local\Packages\PythonSoftwareFoundation.Python.3.9_qbz5n2kfra8p0\LocalCache\local-packages\Python39\site-packages\django\db\backends\utils.py", line 98, in execute
    return super().execute(sql, params)
  File "C:\Users\hp\AppData\Local\Packages\PythonSoftwareFoundation.Python.3.9_qbz5n2kfra8p0\LocalCache\local-packages\Python39\site-packages\django\db\backends\utils.py", line 66, in execute
    return self._execute_with_wrappers(sql, params, many=False, executor=self._execute)
  File "C:\Users\hp\AppData\Local\Packages\PythonSoftwareFoundation.Python.3.9_qbz5n2kfra8p0\LocalCache\local-packages\Python39\site-packages\django\db\backends\utils.py", line 75, in _execute_with_wrappers
    return executor(sql, params, many, context)
  File "C:\Users\hp\AppData\Local\Packages\PythonSoftwareFoundation.Python.3.9_qbz5n2kfra8p0\LocalCache\local-packages\Python39\site-packages\django\db\backends\utils.py", line 84, in _execute
    return self.cursor.execute(sql, params)
  File "C:\Users\hp\AppData\Local\Packages\PythonSoftwareFoundation.Python.3.9_qbz5n2kfra8p0\LocalCache\local-packages\Python39\site-packages\django\db\utils.py", line 90, in __exit__
    raise dj_exc_value.with_traceback(traceback) from exc_value
  File "C:\Users\hp\AppData\Local\Packages\PythonSoftwareFoundation.Python.3.9_qbz5n2kfra8p0\LocalCache\local-packages\Python39\site-packages\django\db\backends\utils.py", line 84, in _execute
    return self.cursor.execute(sql, params)
  File "C:\Users\hp\AppData\Local\Packages\PythonSoftwareFoundation.Python.3.9_qbz5n2kfra8p0\LocalCache\local-packages\Python39\site-packages\django\db\backends\sqlite3\base.py", line 423, in execute
    return Database.Cursor.execute(self, query, params)
django.db.utils.IntegrityError: UNIQUE constraint failed: apps_applists.slug
[2022-07-29T11:01:18] INFO [django.utils.autoreload.trigger_reload:251] C:\Users\hp\Desktop\Internship Assignments\billapp\apps\models.py changed, reloading.
[2022-07-29T11:01:19] DEBUG [asyncio.__init__:624] Using proactor: IocpProactor
[2022-07-29T11:01:24] DEBUG [asyncio.__init__:624] Using proactor: IocpProactor
[2022-07-29T11:01:32] DEBUG [asyncio.__init__:624] Using proactor: IocpProactor
[2022-07-29T11:01:39] DEBUG [asyncio.__init__:624] Using proactor: IocpProactor
[2022-07-29T11:02:09] ERROR [django.request.log_response:224] Internal Server Error: /apps/whatsapp/settings
Traceback (most recent call last):
  File "C:\Users\hp\AppData\Local\Packages\PythonSoftwareFoundation.Python.3.9_qbz5n2kfra8p0\LocalCache\local-packages\Python39\site-packages\django\db\backends\utils.py", line 84, in _execute
    return self.cursor.execute(sql, params)
  File "C:\Users\hp\AppData\Local\Packages\PythonSoftwareFoundation.Python.3.9_qbz5n2kfra8p0\LocalCache\local-packages\Python39\site-packages\django\db\backends\sqlite3\base.py", line 423, in execute
    return Database.Cursor.execute(self, query, params)
sqlite3.IntegrityError: UNIQUE constraint failed: apps_applists.slug

The above exception was the direct cause of the following exception:

Traceback (most recent call last):
  File "C:\Users\hp\AppData\Local\Packages\PythonSoftwareFoundation.Python.3.9_qbz5n2kfra8p0\LocalCache\local-packages\Python39\site-packages\django\core\handlers\exception.py", line 47, in inner
    response = get_response(request)
  File "C:\Users\hp\AppData\Local\Packages\PythonSoftwareFoundation.Python.3.9_qbz5n2kfra8p0\LocalCache\local-packages\Python39\site-packages\django\core\handlers\base.py", line 181, in _get_response
    response = wrapped_callback(request, *callback_args, **callback_kwargs)
  File "C:\Users\hp\Desktop\Internship Assignments\billapp\apps\views.py", line 65, in update_app
    print(form.save())
  File "C:\Users\hp\AppData\Local\Packages\PythonSoftwareFoundation.Python.3.9_qbz5n2kfra8p0\LocalCache\local-packages\Python39\site-packages\django\forms\models.py", line 468, in save
    self.instance.save()
  File "C:\Users\hp\Desktop\Internship Assignments\billapp\apps\models.py", line 33, in save
    super(applists, self).save()
  File "C:\Users\hp\AppData\Local\Packages\PythonSoftwareFoundation.Python.3.9_qbz5n2kfra8p0\LocalCache\local-packages\Python39\site-packages\django\db\models\base.py", line 726, in save
    self.save_base(using=using, force_insert=force_insert,
  File "C:\Users\hp\AppData\Local\Packages\PythonSoftwareFoundation.Python.3.9_qbz5n2kfra8p0\LocalCache\local-packages\Python39\site-packages\django\db\models\base.py", line 763, in save_base
    updated = self._save_table(
  File "C:\Users\hp\AppData\Local\Packages\PythonSoftwareFoundation.Python.3.9_qbz5n2kfra8p0\LocalCache\local-packages\Python39\site-packages\django\db\models\base.py", line 868, in _save_table
    results = self._do_insert(cls._base_manager, using, fields, returning_fields, raw)
  File "C:\Users\hp\AppData\Local\Packages\PythonSoftwareFoundation.Python.3.9_qbz5n2kfra8p0\LocalCache\local-packages\Python39\site-packages\django\db\models\base.py", line 906, in _do_insert
    return manager._insert(
  File "C:\Users\hp\AppData\Local\Packages\PythonSoftwareFoundation.Python.3.9_qbz5n2kfra8p0\LocalCache\local-packages\Python39\site-packages\django\db\models\manager.py", line 85, in manager_method
    return getattr(self.get_queryset(), name)(*args, **kwargs)
  File "C:\Users\hp\AppData\Local\Packages\PythonSoftwareFoundation.Python.3.9_qbz5n2kfra8p0\LocalCache\local-packages\Python39\site-packages\django\db\models\query.py", line 1270, in _insert
    return query.get_compiler(using=using).execute_sql(returning_fields)
  File "C:\Users\hp\AppData\Local\Packages\PythonSoftwareFoundation.Python.3.9_qbz5n2kfra8p0\LocalCache\local-packages\Python39\site-packages\django\db\models\sql\compiler.py", line 1416, in execute_sql
    cursor.execute(sql, params)
  File "C:\Users\hp\AppData\Local\Packages\PythonSoftwareFoundation.Python.3.9_qbz5n2kfra8p0\LocalCache\local-packages\Python39\site-packages\django\db\backends\utils.py", line 98, in execute
    return super().execute(sql, params)
  File "C:\Users\hp\AppData\Local\Packages\PythonSoftwareFoundation.Python.3.9_qbz5n2kfra8p0\LocalCache\local-packages\Python39\site-packages\django\db\backends\utils.py", line 66, in execute
    return self._execute_with_wrappers(sql, params, many=False, executor=self._execute)
  File "C:\Users\hp\AppData\Local\Packages\PythonSoftwareFoundation.Python.3.9_qbz5n2kfra8p0\LocalCache\local-packages\Python39\site-packages\django\db\backends\utils.py", line 75, in _execute_with_wrappers
    return executor(sql, params, many, context)
  File "C:\Users\hp\AppData\Local\Packages\PythonSoftwareFoundation.Python.3.9_qbz5n2kfra8p0\LocalCache\local-packages\Python39\site-packages\django\db\backends\utils.py", line 84, in _execute
    return self.cursor.execute(sql, params)
  File "C:\Users\hp\AppData\Local\Packages\PythonSoftwareFoundation.Python.3.9_qbz5n2kfra8p0\LocalCache\local-packages\Python39\site-packages\django\db\utils.py", line 90, in __exit__
    raise dj_exc_value.with_traceback(traceback) from exc_value
  File "C:\Users\hp\AppData\Local\Packages\PythonSoftwareFoundation.Python.3.9_qbz5n2kfra8p0\LocalCache\local-packages\Python39\site-packages\django\db\backends\utils.py", line 84, in _execute
    return self.cursor.execute(sql, params)
  File "C:\Users\hp\AppData\Local\Packages\PythonSoftwareFoundation.Python.3.9_qbz5n2kfra8p0\LocalCache\local-packages\Python39\site-packages\django\db\backends\sqlite3\base.py", line 423, in execute
    return Database.Cursor.execute(self, query, params)
django.db.utils.IntegrityError: UNIQUE constraint failed: apps_applists.slug
[2022-07-29T11:03:12] INFO [django.utils.autoreload.trigger_reload:251] C:\Users\hp\Desktop\Internship Assignments\billapp\apps\views.py changed, reloading.
[2022-07-29T11:03:14] DEBUG [asyncio.__init__:624] Using proactor: IocpProactor
[2022-07-29T11:03:39] INFO [django.utils.autoreload.trigger_reload:251] C:\Users\hp\Desktop\Internship Assignments\billapp\apps\views.py changed, reloading.
[2022-07-29T11:03:40] DEBUG [asyncio.__init__:624] Using proactor: IocpProactor
[2022-07-29T11:03:53] ERROR [django.request.log_response:224] Internal Server Error: /apps/whatsapp/settings
Traceback (most recent call last):
  File "C:\Users\hp\AppData\Local\Packages\PythonSoftwareFoundation.Python.3.9_qbz5n2kfra8p0\LocalCache\local-packages\Python39\site-packages\django\db\backends\utils.py", line 84, in _execute
    return self.cursor.execute(sql, params)
  File "C:\Users\hp\AppData\Local\Packages\PythonSoftwareFoundation.Python.3.9_qbz5n2kfra8p0\LocalCache\local-packages\Python39\site-packages\django\db\backends\sqlite3\base.py", line 423, in execute
    return Database.Cursor.execute(self, query, params)
sqlite3.IntegrityError: UNIQUE constraint failed: apps_applists.slug

The above exception was the direct cause of the following exception:

Traceback (most recent call last):
  File "C:\Users\hp\AppData\Local\Packages\PythonSoftwareFoundation.Python.3.9_qbz5n2kfra8p0\LocalCache\local-packages\Python39\site-packages\django\core\handlers\exception.py", line 47, in inner
    response = get_response(request)
  File "C:\Users\hp\AppData\Local\Packages\PythonSoftwareFoundation.Python.3.9_qbz5n2kfra8p0\LocalCache\local-packages\Python39\site-packages\django\core\handlers\base.py", line 181, in _get_response
    response = wrapped_callback(request, *callback_args, **callback_kwargs)
  File "C:\Users\hp\Desktop\Internship Assignments\billapp\apps\views.py", line 68, in update_app
    app.save(update_fields=['author', 'appname', 'appimg'])
  File "C:\Users\hp\Desktop\Internship Assignments\billapp\apps\models.py", line 33, in save
    super(applists, self).save()
  File "C:\Users\hp\AppData\Local\Packages\PythonSoftwareFoundation.Python.3.9_qbz5n2kfra8p0\LocalCache\local-packages\Python39\site-packages\django\db\models\base.py", line 726, in save
    self.save_base(using=using, force_insert=force_insert,
  File "C:\Users\hp\AppData\Local\Packages\PythonSoftwareFoundation.Python.3.9_qbz5n2kfra8p0\LocalCache\local-packages\Python39\site-packages\django\db\models\base.py", line 763, in save_base
    updated = self._save_table(
  File "C:\Users\hp\AppData\Local\Packages\PythonSoftwareFoundation.Python.3.9_qbz5n2kfra8p0\LocalCache\local-packages\Python39\site-packages\django\db\models\base.py", line 868, in _save_table
    results = self._do_insert(cls._base_manager, using, fields, returning_fields, raw)
  File "C:\Users\hp\AppData\Local\Packages\PythonSoftwareFoundation.Python.3.9_qbz5n2kfra8p0\LocalCache\local-packages\Python39\site-packages\django\db\models\base.py", line 906, in _do_insert
    return manager._insert(
  File "C:\Users\hp\AppData\Local\Packages\PythonSoftwareFoundation.Python.3.9_qbz5n2kfra8p0\LocalCache\local-packages\Python39\site-packages\django\db\models\manager.py", line 85, in manager_method
    return getattr(self.get_queryset(), name)(*args, **kwargs)
  File "C:\Users\hp\AppData\Local\Packages\PythonSoftwareFoundation.Python.3.9_qbz5n2kfra8p0\LocalCache\local-packages\Python39\site-packages\django\db\models\query.py", line 1270, in _insert
    return query.get_compiler(using=using).execute_sql(returning_fields)
  File "C:\Users\hp\AppData\Local\Packages\PythonSoftwareFoundation.Python.3.9_qbz5n2kfra8p0\LocalCache\local-packages\Python39\site-packages\django\db\models\sql\compiler.py", line 1416, in execute_sql
    cursor.execute(sql, params)
  File "C:\Users\hp\AppData\Local\Packages\PythonSoftwareFoundation.Python.3.9_qbz5n2kfra8p0\LocalCache\local-packages\Python39\site-packages\django\db\backends\utils.py", line 98, in execute
    return super().execute(sql, params)
  File "C:\Users\hp\AppData\Local\Packages\PythonSoftwareFoundation.Python.3.9_qbz5n2kfra8p0\LocalCache\local-packages\Python39\site-packages\django\db\backends\utils.py", line 66, in execute
    return self._execute_with_wrappers(sql, params, many=False, executor=self._execute)
  File "C:\Users\hp\AppData\Local\Packages\PythonSoftwareFoundation.Python.3.9_qbz5n2kfra8p0\LocalCache\local-packages\Python39\site-packages\django\db\backends\utils.py", line 75, in _execute_with_wrappers
    return executor(sql, params, many, context)
  File "C:\Users\hp\AppData\Local\Packages\PythonSoftwareFoundation.Python.3.9_qbz5n2kfra8p0\LocalCache\local-packages\Python39\site-packages\django\db\backends\utils.py", line 84, in _execute
    return self.cursor.execute(sql, params)
  File "C:\Users\hp\AppData\Local\Packages\PythonSoftwareFoundation.Python.3.9_qbz5n2kfra8p0\LocalCache\local-packages\Python39\site-packages\django\db\utils.py", line 90, in __exit__
    raise dj_exc_value.with_traceback(traceback) from exc_value
  File "C:\Users\hp\AppData\Local\Packages\PythonSoftwareFoundation.Python.3.9_qbz5n2kfra8p0\LocalCache\local-packages\Python39\site-packages\django\db\backends\utils.py", line 84, in _execute
    return self.cursor.execute(sql, params)
  File "C:\Users\hp\AppData\Local\Packages\PythonSoftwareFoundation.Python.3.9_qbz5n2kfra8p0\LocalCache\local-packages\Python39\site-packages\django\db\backends\sqlite3\base.py", line 423, in execute
    return Database.Cursor.execute(self, query, params)
django.db.utils.IntegrityError: UNIQUE constraint failed: apps_applists.slug
[2022-07-29T11:04:34] INFO [django.utils.autoreload.trigger_reload:251] C:\Users\hp\Desktop\Internship Assignments\billapp\apps\views.py changed, reloading.
[2022-07-29T11:04:35] DEBUG [asyncio.__init__:624] Using proactor: IocpProactor
[2022-07-29T11:04:55] DEBUG [PIL.Image.init:399] Importing BlpImagePlugin
[2022-07-29T11:04:55] DEBUG [PIL.Image.init:399] Importing BmpImagePlugin
[2022-07-29T11:04:55] DEBUG [PIL.Image.init:399] Importing BufrStubImagePlugin
[2022-07-29T11:04:55] DEBUG [PIL.Image.init:399] Importing CurImagePlugin
[2022-07-29T11:04:55] DEBUG [PIL.Image.init:399] Importing DcxImagePlugin
[2022-07-29T11:04:55] DEBUG [PIL.Image.init:399] Importing DdsImagePlugin
[2022-07-29T11:04:55] DEBUG [PIL.Image.init:399] Importing EpsImagePlugin
[2022-07-29T11:04:55] DEBUG [PIL.Image.init:399] Importing FitsStubImagePlugin
[2022-07-29T11:04:55] DEBUG [PIL.Image.init:399] Importing FliImagePlugin
[2022-07-29T11:04:55] DEBUG [PIL.Image.init:399] Importing FpxImagePlugin
[2022-07-29T11:04:55] DEBUG [PIL.Image.init:402] Image: failed to import FpxImagePlugin: No module named 'olefile'
[2022-07-29T11:04:55] DEBUG [PIL.Image.init:399] Importing FtexImagePlugin
[2022-07-29T11:04:55] DEBUG [PIL.Image.init:399] Importing GbrImagePlugin
[2022-07-29T11:04:55] DEBUG [PIL.Image.init:399] Importing GifImagePlugin
[2022-07-29T11:04:55] DEBUG [PIL.Image.init:399] Importing GribStubImagePlugin
[2022-07-29T11:04:55] DEBUG [PIL.Image.init:399] Importing Hdf5StubImagePlugin
[2022-07-29T11:04:55] DEBUG [PIL.Image.init:399] Importing IcnsImagePlugin
[2022-07-29T11:04:55] DEBUG [PIL.Image.init:399] Importing IcoImagePlugin
[2022-07-29T11:04:55] DEBUG [PIL.Image.init:399] Importing ImImagePlugin
[2022-07-29T11:04:55] DEBUG [PIL.Image.init:399] Importing ImtImagePlugin
[2022-07-29T11:04:55] DEBUG [PIL.Image.init:399] Importing IptcImagePlugin
[2022-07-29T11:04:55] DEBUG [PIL.Image.init:399] Importing JpegImagePlugin
[2022-07-29T11:04:55] DEBUG [PIL.Image.init:399] Importing Jpeg2KImagePlugin
[2022-07-29T11:04:55] DEBUG [PIL.Image.init:399] Importing McIdasImagePlugin
[2022-07-29T11:04:55] DEBUG [PIL.Image.init:399] Importing MicImagePlugin
[2022-07-29T11:04:55] DEBUG [PIL.Image.init:402] Image: failed to import MicImagePlugin: No module named 'olefile'
[2022-07-29T11:04:55] DEBUG [PIL.Image.init:399] Importing MpegImagePlugin
[2022-07-29T11:04:55] DEBUG [PIL.Image.init:399] Importing MpoImagePlugin
[2022-07-29T11:04:55] DEBUG [PIL.Image.init:399] Importing MspImagePlugin
[2022-07-29T11:04:55] DEBUG [PIL.Image.init:399] Importing PalmImagePlugin
[2022-07-29T11:04:55] DEBUG [PIL.Image.init:399] Importing PcdImagePlugin
[2022-07-29T11:04:55] DEBUG [PIL.Image.init:399] Importing PcxImagePlugin
[2022-07-29T11:04:55] DEBUG [PIL.Image.init:399] Importing PdfImagePlugin
[2022-07-29T11:04:55] DEBUG [PIL.Image.init:399] Importing PixarImagePlugin
[2022-07-29T11:04:55] DEBUG [PIL.Image.init:399] Importing PngImagePlugin
[2022-07-29T11:04:55] DEBUG [PIL.Image.init:399] Importing PpmImagePlugin
[2022-07-29T11:04:55] DEBUG [PIL.Image.init:399] Importing PsdImagePlugin
[2022-07-29T11:04:55] DEBUG [PIL.Image.init:399] Importing SgiImagePlugin
[2022-07-29T11:04:55] DEBUG [PIL.Image.init:399] Importing SpiderImagePlugin
[2022-07-29T11:04:55] DEBUG [PIL.Image.init:399] Importing SunImagePlugin
[2022-07-29T11:04:55] DEBUG [PIL.Image.init:399] Importing TgaImagePlugin
[2022-07-29T11:04:55] DEBUG [PIL.Image.init:399] Importing TiffImagePlugin
[2022-07-29T11:04:55] DEBUG [PIL.Image.init:399] Importing WebPImagePlugin
[2022-07-29T11:04:55] DEBUG [PIL.Image.init:399] Importing WmfImagePlugin
[2022-07-29T11:04:55] DEBUG [PIL.Image.init:399] Importing XbmImagePlugin
[2022-07-29T11:04:55] DEBUG [PIL.Image.init:399] Importing XpmImagePlugin
[2022-07-29T11:04:55] DEBUG [PIL.Image.init:399] Importing XVThumbImagePlugin
[2022-07-29T11:04:55] ERROR [django.request.log_response:224] Internal Server Error: /apps/whatsapp/settings
Traceback (most recent call last):
  File "C:\Users\hp\AppData\Local\Packages\PythonSoftwareFoundation.Python.3.9_qbz5n2kfra8p0\LocalCache\local-packages\Python39\site-packages\django\db\backends\utils.py", line 84, in _execute
    return self.cursor.execute(sql, params)
  File "C:\Users\hp\AppData\Local\Packages\PythonSoftwareFoundation.Python.3.9_qbz5n2kfra8p0\LocalCache\local-packages\Python39\site-packages\django\db\backends\sqlite3\base.py", line 423, in execute
    return Database.Cursor.execute(self, query, params)
sqlite3.IntegrityError: UNIQUE constraint failed: apps_applists.slug

The above exception was the direct cause of the following exception:

Traceback (most recent call last):
  File "C:\Users\hp\AppData\Local\Packages\PythonSoftwareFoundation.Python.3.9_qbz5n2kfra8p0\LocalCache\local-packages\Python39\site-packages\django\core\handlers\exception.py", line 47, in inner
    response = get_response(request)
  File "C:\Users\hp\AppData\Local\Packages\PythonSoftwareFoundation.Python.3.9_qbz5n2kfra8p0\LocalCache\local-packages\Python39\site-packages\django\core\handlers\base.py", line 181, in _get_response
    response = wrapped_callback(request, *callback_args, **callback_kwargs)
  File "C:\Users\hp\Desktop\Internship Assignments\billapp\apps\views.py", line 68, in update_app
    app.save(update_fields=['author', 'appimg'])
  File "C:\Users\hp\Desktop\Internship Assignments\billapp\apps\models.py", line 33, in save
    super(applists, self).save()
  File "C:\Users\hp\AppData\Local\Packages\PythonSoftwareFoundation.Python.3.9_qbz5n2kfra8p0\LocalCache\local-packages\Python39\site-packages\django\db\models\base.py", line 726, in save
    self.save_base(using=using, force_insert=force_insert,
  File "C:\Users\hp\AppData\Local\Packages\PythonSoftwareFoundation.Python.3.9_qbz5n2kfra8p0\LocalCache\local-packages\Python39\site-packages\django\db\models\base.py", line 763, in save_base
    updated = self._save_table(
  File "C:\Users\hp\AppData\Local\Packages\PythonSoftwareFoundation.Python.3.9_qbz5n2kfra8p0\LocalCache\local-packages\Python39\site-packages\django\db\models\base.py", line 868, in _save_table
    results = self._do_insert(cls._base_manager, using, fields, returning_fields, raw)
  File "C:\Users\hp\AppData\Local\Packages\PythonSoftwareFoundation.Python.3.9_qbz5n2kfra8p0\LocalCache\local-packages\Python39\site-packages\django\db\models\base.py", line 906, in _do_insert
    return manager._insert(
  File "C:\Users\hp\AppData\Local\Packages\PythonSoftwareFoundation.Python.3.9_qbz5n2kfra8p0\LocalCache\local-packages\Python39\site-packages\django\db\models\manager.py", line 85, in manager_method
    return getattr(self.get_queryset(), name)(*args, **kwargs)
  File "C:\Users\hp\AppData\Local\Packages\PythonSoftwareFoundation.Python.3.9_qbz5n2kfra8p0\LocalCache\local-packages\Python39\site-packages\django\db\models\query.py", line 1270, in _insert
    return query.get_compiler(using=using).execute_sql(returning_fields)
  File "C:\Users\hp\AppData\Local\Packages\PythonSoftwareFoundation.Python.3.9_qbz5n2kfra8p0\LocalCache\local-packages\Python39\site-packages\django\db\models\sql\compiler.py", line 1416, in execute_sql
    cursor.execute(sql, params)
  File "C:\Users\hp\AppData\Local\Packages\PythonSoftwareFoundation.Python.3.9_qbz5n2kfra8p0\LocalCache\local-packages\Python39\site-packages\django\db\backends\utils.py", line 98, in execute
    return super().execute(sql, params)
  File "C:\Users\hp\AppData\Local\Packages\PythonSoftwareFoundation.Python.3.9_qbz5n2kfra8p0\LocalCache\local-packages\Python39\site-packages\django\db\backends\utils.py", line 66, in execute
    return self._execute_with_wrappers(sql, params, many=False, executor=self._execute)
  File "C:\Users\hp\AppData\Local\Packages\PythonSoftwareFoundation.Python.3.9_qbz5n2kfra8p0\LocalCache\local-packages\Python39\site-packages\django\db\backends\utils.py", line 75, in _execute_with_wrappers
    return executor(sql, params, many, context)
  File "C:\Users\hp\AppData\Local\Packages\PythonSoftwareFoundation.Python.3.9_qbz5n2kfra8p0\LocalCache\local-packages\Python39\site-packages\django\db\backends\utils.py", line 84, in _execute
    return self.cursor.execute(sql, params)
  File "C:\Users\hp\AppData\Local\Packages\PythonSoftwareFoundation.Python.3.9_qbz5n2kfra8p0\LocalCache\local-packages\Python39\site-packages\django\db\utils.py", line 90, in __exit__
    raise dj_exc_value.with_traceback(traceback) from exc_value
  File "C:\Users\hp\AppData\Local\Packages\PythonSoftwareFoundation.Python.3.9_qbz5n2kfra8p0\LocalCache\local-packages\Python39\site-packages\django\db\backends\utils.py", line 84, in _execute
    return self.cursor.execute(sql, params)
  File "C:\Users\hp\AppData\Local\Packages\PythonSoftwareFoundation.Python.3.9_qbz5n2kfra8p0\LocalCache\local-packages\Python39\site-packages\django\db\backends\sqlite3\base.py", line 423, in execute
    return Database.Cursor.execute(self, query, params)
django.db.utils.IntegrityError: UNIQUE constraint failed: apps_applists.slug
[2022-07-29T11:08:41] INFO [django.utils.autoreload.trigger_reload:251] C:\Users\hp\Desktop\Internship Assignments\billapp\apps\forms.py changed, reloading.
[2022-07-29T11:08:59] ERROR [django.request.log_response:224] Internal Server Error: /apps/whatsapp/settings
Traceback (most recent call last):
  File "C:\Users\hp\AppData\Local\Packages\PythonSoftwareFoundation.Python.3.9_qbz5n2kfra8p0\LocalCache\local-packages\Python39\site-packages\django\db\models\fields\__init__.py", line 1823, in get_prep_value
    return int(value)
TypeError: int() argument must be a string, a bytes-like object or a number, not 'User'

The above exception was the direct cause of the following exception:

Traceback (most recent call last):
  File "C:\Users\hp\AppData\Local\Packages\PythonSoftwareFoundation.Python.3.9_qbz5n2kfra8p0\LocalCache\local-packages\Python39\site-packages\django\core\handlers\exception.py", line 47, in inner
    response = get_response(request)
  File "C:\Users\hp\AppData\Local\Packages\PythonSoftwareFoundation.Python.3.9_qbz5n2kfra8p0\LocalCache\local-packages\Python39\site-packages\django\core\handlers\base.py", line 181, in _get_response
    response = wrapped_callback(request, *callback_args, **callback_kwargs)
  File "C:\Users\hp\Desktop\Internship Assignments\billapp\apps\views.py", line 67, in update_app
    app.author = User.objects.get(id=form.cleaned_data.get('author'))
  File "C:\Users\hp\AppData\Local\Packages\PythonSoftwareFoundation.Python.3.9_qbz5n2kfra8p0\LocalCache\local-packages\Python39\site-packages\django\db\models\manager.py", line 85, in manager_method
    return getattr(self.get_queryset(), name)(*args, **kwargs)
  File "C:\Users\hp\AppData\Local\Packages\PythonSoftwareFoundation.Python.3.9_qbz5n2kfra8p0\LocalCache\local-packages\Python39\site-packages\django\db\models\query.py", line 424, in get
    clone = self._chain() if self.query.combinator else self.filter(*args, **kwargs)
  File "C:\Users\hp\AppData\Local\Packages\PythonSoftwareFoundation.Python.3.9_qbz5n2kfra8p0\LocalCache\local-packages\Python39\site-packages\django\db\models\query.py", line 941, in filter
    return self._filter_or_exclude(False, args, kwargs)
  File "C:\Users\hp\AppData\Local\Packages\PythonSoftwareFoundation.Python.3.9_qbz5n2kfra8p0\LocalCache\local-packages\Python39\site-packages\django\db\models\query.py", line 961, in _filter_or_exclude
    clone._filter_or_exclude_inplace(negate, args, kwargs)
  File "C:\Users\hp\AppData\Local\Packages\PythonSoftwareFoundation.Python.3.9_qbz5n2kfra8p0\LocalCache\local-packages\Python39\site-packages\django\db\models\query.py", line 968, in _filter_or_exclude_inplace
    self._query.add_q(Q(*args, **kwargs))
  File "C:\Users\hp\AppData\Local\Packages\PythonSoftwareFoundation.Python.3.9_qbz5n2kfra8p0\LocalCache\local-packages\Python39\site-packages\django\db\models\sql\query.py", line 1393, in add_q
    clause, _ = self._add_q(q_object, self.used_aliases)
  File "C:\Users\hp\AppData\Local\Packages\PythonSoftwareFoundation.Python.3.9_qbz5n2kfra8p0\LocalCache\local-packages\Python39\site-packages\django\db\models\sql\query.py", line 1412, in _add_q
    child_clause, needed_inner = self.build_filter(
  File "C:\Users\hp\AppData\Local\Packages\PythonSoftwareFoundation.Python.3.9_qbz5n2kfra8p0\LocalCache\local-packages\Python39\site-packages\django\db\models\sql\query.py", line 1347, in build_filter
    condition = self.build_lookup(lookups, col, value)
  File "C:\Users\hp\AppData\Local\Packages\PythonSoftwareFoundation.Python.3.9_qbz5n2kfra8p0\LocalCache\local-packages\Python39\site-packages\django\db\models\sql\query.py", line 1193, in build_lookup
    lookup = lookup_class(lhs, rhs)
  File "C:\Users\hp\AppData\Local\Packages\PythonSoftwareFoundation.Python.3.9_qbz5n2kfra8p0\LocalCache\local-packages\Python39\site-packages\django\db\models\lookups.py", line 25, in __init__
    self.rhs = self.get_prep_lookup()
  File "C:\Users\hp\AppData\Local\Packages\PythonSoftwareFoundation.Python.3.9_qbz5n2kfra8p0\LocalCache\local-packages\Python39\site-packages\django\db\models\lookups.py", line 77, in get_prep_lookup
    return self.lhs.output_field.get_prep_value(self.rhs)
  File "C:\Users\hp\AppData\Local\Packages\PythonSoftwareFoundation.Python.3.9_qbz5n2kfra8p0\LocalCache\local-packages\Python39\site-packages\django\db\models\fields\__init__.py", line 1825, in get_prep_value
    raise e.__class__(
TypeError: Field 'id' expected a number but got <User: hp>.
[2022-07-29T11:09:16] INFO [django.utils.autoreload.trigger_reload:251] C:\Users\hp\Desktop\Internship Assignments\billapp\apps\views.py changed, reloading.
[2022-07-29T11:09:16] DEBUG [asyncio.__init__:624] Using proactor: IocpProactor
[2022-07-29T11:09:35] ERROR [django.request.log_response:224] Internal Server Error: /apps/whatsapp/settings
Traceback (most recent call last):
  File "C:\Users\hp\AppData\Local\Packages\PythonSoftwareFoundation.Python.3.9_qbz5n2kfra8p0\LocalCache\local-packages\Python39\site-packages\django\db\backends\utils.py", line 84, in _execute
    return self.cursor.execute(sql, params)
  File "C:\Users\hp\AppData\Local\Packages\PythonSoftwareFoundation.Python.3.9_qbz5n2kfra8p0\LocalCache\local-packages\Python39\site-packages\django\db\backends\sqlite3\base.py", line 423, in execute
    return Database.Cursor.execute(self, query, params)
sqlite3.IntegrityError: UNIQUE constraint failed: apps_applists.slug

The above exception was the direct cause of the following exception:

Traceback (most recent call last):
  File "C:\Users\hp\AppData\Local\Packages\PythonSoftwareFoundation.Python.3.9_qbz5n2kfra8p0\LocalCache\local-packages\Python39\site-packages\django\core\handlers\exception.py", line 47, in inner
    response = get_response(request)
  File "C:\Users\hp\AppData\Local\Packages\PythonSoftwareFoundation.Python.3.9_qbz5n2kfra8p0\LocalCache\local-packages\Python39\site-packages\django\core\handlers\base.py", line 181, in _get_response
    response = wrapped_callback(request, *callback_args, **callback_kwargs)
  File "C:\Users\hp\Desktop\Internship Assignments\billapp\apps\views.py", line 68, in update_app
    app.save(update_fields=['author', 'appimg'])
  File "C:\Users\hp\Desktop\Internship Assignments\billapp\apps\models.py", line 33, in save
    super(applists, self).save()
  File "C:\Users\hp\AppData\Local\Packages\PythonSoftwareFoundation.Python.3.9_qbz5n2kfra8p0\LocalCache\local-packages\Python39\site-packages\django\db\models\base.py", line 726, in save
    self.save_base(using=using, force_insert=force_insert,
  File "C:\Users\hp\AppData\Local\Packages\PythonSoftwareFoundation.Python.3.9_qbz5n2kfra8p0\LocalCache\local-packages\Python39\site-packages\django\db\models\base.py", line 763, in save_base
    updated = self._save_table(
  File "C:\Users\hp\AppData\Local\Packages\PythonSoftwareFoundation.Python.3.9_qbz5n2kfra8p0\LocalCache\local-packages\Python39\site-packages\django\db\models\base.py", line 868, in _save_table
    results = self._do_insert(cls._base_manager, using, fields, returning_fields, raw)
  File "C:\Users\hp\AppData\Local\Packages\PythonSoftwareFoundation.Python.3.9_qbz5n2kfra8p0\LocalCache\local-packages\Python39\site-packages\django\db\models\base.py", line 906, in _do_insert
    return manager._insert(
  File "C:\Users\hp\AppData\Local\Packages\PythonSoftwareFoundation.Python.3.9_qbz5n2kfra8p0\LocalCache\local-packages\Python39\site-packages\django\db\models\manager.py", line 85, in manager_method
    return getattr(self.get_queryset(), name)(*args, **kwargs)
  File "C:\Users\hp\AppData\Local\Packages\PythonSoftwareFoundation.Python.3.9_qbz5n2kfra8p0\LocalCache\local-packages\Python39\site-packages\django\db\models\query.py", line 1270, in _insert
    return query.get_compiler(using=using).execute_sql(returning_fields)
  File "C:\Users\hp\AppData\Local\Packages\PythonSoftwareFoundation.Python.3.9_qbz5n2kfra8p0\LocalCache\local-packages\Python39\site-packages\django\db\models\sql\compiler.py", line 1416, in execute_sql
    cursor.execute(sql, params)
  File "C:\Users\hp\AppData\Local\Packages\PythonSoftwareFoundation.Python.3.9_qbz5n2kfra8p0\LocalCache\local-packages\Python39\site-packages\django\db\backends\utils.py", line 98, in execute
    return super().execute(sql, params)
  File "C:\Users\hp\AppData\Local\Packages\PythonSoftwareFoundation.Python.3.9_qbz5n2kfra8p0\LocalCache\local-packages\Python39\site-packages\django\db\backends\utils.py", line 66, in execute
    return self._execute_with_wrappers(sql, params, many=False, executor=self._execute)
  File "C:\Users\hp\AppData\Local\Packages\PythonSoftwareFoundation.Python.3.9_qbz5n2kfra8p0\LocalCache\local-packages\Python39\site-packages\django\db\backends\utils.py", line 75, in _execute_with_wrappers
    return executor(sql, params, many, context)
  File "C:\Users\hp\AppData\Local\Packages\PythonSoftwareFoundation.Python.3.9_qbz5n2kfra8p0\LocalCache\local-packages\Python39\site-packages\django\db\backends\utils.py", line 84, in _execute
    return self.cursor.execute(sql, params)
  File "C:\Users\hp\AppData\Local\Packages\PythonSoftwareFoundation.Python.3.9_qbz5n2kfra8p0\LocalCache\local-packages\Python39\site-packages\django\db\utils.py", line 90, in __exit__
    raise dj_exc_value.with_traceback(traceback) from exc_value
  File "C:\Users\hp\AppData\Local\Packages\PythonSoftwareFoundation.Python.3.9_qbz5n2kfra8p0\LocalCache\local-packages\Python39\site-packages\django\db\backends\utils.py", line 84, in _execute
    return self.cursor.execute(sql, params)
  File "C:\Users\hp\AppData\Local\Packages\PythonSoftwareFoundation.Python.3.9_qbz5n2kfra8p0\LocalCache\local-packages\Python39\site-packages\django\db\backends\sqlite3\base.py", line 423, in execute
    return Database.Cursor.execute(self, query, params)
django.db.utils.IntegrityError: UNIQUE constraint failed: apps_applists.slug
[2022-07-29T11:10:21] INFO [django.utils.autoreload.trigger_reload:251] C:\Users\hp\Desktop\Internship Assignments\billapp\apps\forms.py changed, reloading.
[2022-07-29T11:10:21] DEBUG [asyncio.__init__:624] Using proactor: IocpProactor
[2022-07-29T11:10:47] DEBUG [PIL.Image.init:399] Importing BlpImagePlugin
[2022-07-29T11:10:47] DEBUG [PIL.Image.init:399] Importing BmpImagePlugin
[2022-07-29T11:10:47] DEBUG [PIL.Image.init:399] Importing BufrStubImagePlugin
[2022-07-29T11:10:47] DEBUG [PIL.Image.init:399] Importing CurImagePlugin
[2022-07-29T11:10:47] DEBUG [PIL.Image.init:399] Importing DcxImagePlugin
[2022-07-29T11:10:47] DEBUG [PIL.Image.init:399] Importing DdsImagePlugin
[2022-07-29T11:10:47] DEBUG [PIL.Image.init:399] Importing EpsImagePlugin
[2022-07-29T11:10:47] DEBUG [PIL.Image.init:399] Importing FitsStubImagePlugin
[2022-07-29T11:10:47] DEBUG [PIL.Image.init:399] Importing FliImagePlugin
[2022-07-29T11:10:47] DEBUG [PIL.Image.init:399] Importing FpxImagePlugin
[2022-07-29T11:10:47] DEBUG [PIL.Image.init:402] Image: failed to import FpxImagePlugin: No module named 'olefile'
[2022-07-29T11:10:47] DEBUG [PIL.Image.init:399] Importing FtexImagePlugin
[2022-07-29T11:10:47] DEBUG [PIL.Image.init:399] Importing GbrImagePlugin
[2022-07-29T11:10:47] DEBUG [PIL.Image.init:399] Importing GifImagePlugin
[2022-07-29T11:10:47] DEBUG [PIL.Image.init:399] Importing GribStubImagePlugin
[2022-07-29T11:10:47] DEBUG [PIL.Image.init:399] Importing Hdf5StubImagePlugin
[2022-07-29T11:10:47] DEBUG [PIL.Image.init:399] Importing IcnsImagePlugin
[2022-07-29T11:10:47] DEBUG [PIL.Image.init:399] Importing IcoImagePlugin
[2022-07-29T11:10:47] DEBUG [PIL.Image.init:399] Importing ImImagePlugin
[2022-07-29T11:10:47] DEBUG [PIL.Image.init:399] Importing ImtImagePlugin
[2022-07-29T11:10:47] DEBUG [PIL.Image.init:399] Importing IptcImagePlugin
[2022-07-29T11:10:47] DEBUG [PIL.Image.init:399] Importing JpegImagePlugin
[2022-07-29T11:10:47] DEBUG [PIL.Image.init:399] Importing Jpeg2KImagePlugin
[2022-07-29T11:10:47] DEBUG [PIL.Image.init:399] Importing McIdasImagePlugin
[2022-07-29T11:10:47] DEBUG [PIL.Image.init:399] Importing MicImagePlugin
[2022-07-29T11:10:47] DEBUG [PIL.Image.init:402] Image: failed to import MicImagePlugin: No module named 'olefile'
[2022-07-29T11:10:47] DEBUG [PIL.Image.init:399] Importing MpegImagePlugin
[2022-07-29T11:10:47] DEBUG [PIL.Image.init:399] Importing MpoImagePlugin
[2022-07-29T11:10:47] DEBUG [PIL.Image.init:399] Importing MspImagePlugin
[2022-07-29T11:10:47] DEBUG [PIL.Image.init:399] Importing PalmImagePlugin
[2022-07-29T11:10:47] DEBUG [PIL.Image.init:399] Importing PcdImagePlugin
[2022-07-29T11:10:47] DEBUG [PIL.Image.init:399] Importing PcxImagePlugin
[2022-07-29T11:10:47] DEBUG [PIL.Image.init:399] Importing PdfImagePlugin
[2022-07-29T11:10:47] DEBUG [PIL.Image.init:399] Importing PixarImagePlugin
[2022-07-29T11:10:47] DEBUG [PIL.Image.init:399] Importing PngImagePlugin
[2022-07-29T11:10:47] DEBUG [PIL.Image.init:399] Importing PpmImagePlugin
[2022-07-29T11:10:47] DEBUG [PIL.Image.init:399] Importing PsdImagePlugin
[2022-07-29T11:10:47] DEBUG [PIL.Image.init:399] Importing SgiImagePlugin
[2022-07-29T11:10:47] DEBUG [PIL.Image.init:399] Importing SpiderImagePlugin
[2022-07-29T11:10:47] DEBUG [PIL.Image.init:399] Importing SunImagePlugin
[2022-07-29T11:10:47] DEBUG [PIL.Image.init:399] Importing TgaImagePlugin
[2022-07-29T11:10:47] DEBUG [PIL.Image.init:399] Importing TiffImagePlugin
[2022-07-29T11:10:47] DEBUG [PIL.Image.init:399] Importing WebPImagePlugin
[2022-07-29T11:10:47] DEBUG [PIL.Image.init:399] Importing WmfImagePlugin
[2022-07-29T11:10:47] DEBUG [PIL.Image.init:399] Importing XbmImagePlugin
[2022-07-29T11:10:47] DEBUG [PIL.Image.init:399] Importing XpmImagePlugin
[2022-07-29T11:10:47] DEBUG [PIL.Image.init:399] Importing XVThumbImagePlugin
[2022-07-29T11:10:59] WARNING [django.request.log_response:224] Not Found: /hp/js/create.js
[2022-07-29T11:11:20] WARNING [django.request.log_response:224] Not Found: /hp/js/create.js
[2022-07-29T11:14:05] WARNING [django.request.log_response:224] Not Found: /hp/js/create.js
[2022-07-29T11:14:07] WARNING [django.request.log_response:224] Not Found: /apps/dashboard.html/dashboard/assets/css/styles.css
[2022-07-29T11:14:07] WARNING [django.request.log_response:224] Not Found: /apps/dashboard.html/dashboard/assets/img/illustrations/rocket-white.png
[2022-07-29T11:14:07] WARNING [django.request.log_response:224] Not Found: /apps/dashboard.html/dashboard/assets/img/small-logos/logo-xd.svg
[2022-07-29T11:14:07] WARNING [django.request.log_response:224] Not Found: /apps/dashboard.html/dashboard/assets/css/styles.css
[2022-07-29T11:14:07] WARNING [django.request.log_response:224] Not Found: /apps/dashboard.html/dashboard/assets/img/team-1.jpg
[2022-07-29T11:14:07] WARNING [django.request.log_response:224] Not Found: /apps/dashboard.html/dashboard/assets/img/team-2.jpg
[2022-07-29T11:14:07] WARNING [django.request.log_response:224] Not Found: /apps/dashboard.html/dashboard/assets/img/small-logos/logo-slack.svg
[2022-07-29T11:14:07] WARNING [django.request.log_response:224] Not Found: /apps/dashboard.html/dashboard/assets/img/team-3.jpg
[2022-07-29T11:14:07] WARNING [django.request.log_response:224] Not Found: /apps/dashboard.html/dashboard/assets/img/team-4.jpg
[2022-07-29T11:14:07] WARNING [django.request.log_response:224] Not Found: /apps/dashboard.html/dashboard/assets/img/small-logos/logo-atlassian.svg
[2022-07-29T11:14:07] WARNING [django.request.log_response:224] Not Found: /apps/dashboard.html/dashboard/assets/img/small-logos/logo-spotify.svg
[2022-07-29T11:14:07] WARNING [django.request.log_response:224] Not Found: /apps/dashboard.html/dashboard/assets/img/small-logos/logo-jira.svg
[2022-07-29T11:14:07] WARNING [django.request.log_response:224] Not Found: /apps/dashboard.html/dashboard/assets/img/small-logos/logo-invision.svg
[2022-07-29T11:14:07] WARNING [django.request.log_response:224] Not Found: /apps/dashboard.html/dashboard/assets/js/plugins/chartjs.min.js
[2022-07-29T11:14:07] WARNING [django.request.log_response:224] Not Found: /apps/dashboard.html/dashboard/assets/js/plugins/perfect-scrollbar.min.js
[2022-07-29T11:14:07] WARNING [django.request.log_response:224] Not Found: /apps/dashboard.html/dashboard/assets/img/ivancik.jpg
[2022-07-29T11:14:07] WARNING [django.request.log_response:224] Not Found: /apps/dashboard.html/dashboard/assets/img/team-2.jpg
[2022-07-29T11:14:07] WARNING [django.request.log_response:224] Not Found: /apps/dashboard.html/dashboard/assets/img/team-1.jpg
[2022-07-29T11:17:02] WARNING [django.request.log_response:224] Not Found: /hp/js/create.js
[2022-07-29T11:18:14] WARNING [django.request.log_response:224] Not Found: /hp/js/create.js
[2022-07-29T11:19:39] WARNING [django.request.log_response:224] Not Found: /apps/whatsapp/dashboard/assets/css/styles.css
[2022-07-29T11:19:39] WARNING [django.request.log_response:224] Not Found: /apps/whatsapp/dashboard/assets/img/illustrations/rocket-white.png
[2022-07-29T11:19:39] WARNING [django.request.log_response:224] Not Found: /apps/whatsapp/dashboard/assets/img/small-logos/logo-xd.svg
[2022-07-29T11:19:39] WARNING [django.request.log_response:224] Not Found: /apps/whatsapp/dashboard/assets/css/styles.css
[2022-07-29T11:19:39] WARNING [django.request.log_response:224] Not Found: /apps/whatsapp/dashboard/assets/img/team-1.jpg
[2022-07-29T11:19:39] WARNING [django.request.log_response:224] Not Found: /apps/whatsapp/dashboard/assets/img/team-2.jpg
[2022-07-29T11:19:39] WARNING [django.request.log_response:224] Not Found: /apps/whatsapp/dashboard/assets/img/team-3.jpg
[2022-07-29T11:19:39] WARNING [django.request.log_response:224] Not Found: /apps/whatsapp/dashboard/assets/img/team-4.jpg
[2022-07-29T11:19:39] WARNING [django.request.log_response:224] Not Found: /apps/whatsapp/dashboard/assets/img/small-logos/logo-atlassian.svg
[2022-07-29T11:19:39] WARNING [django.request.log_response:224] Not Found: /apps/whatsapp/dashboard/assets/img/small-logos/logo-slack.svg
[2022-07-29T11:19:39] WARNING [django.request.log_response:224] Not Found: /apps/whatsapp/dashboard/assets/img/small-logos/logo-spotify.svg
[2022-07-29T11:19:39] WARNING [django.request.log_response:224] Not Found: /apps/whatsapp/dashboard/assets/img/small-logos/logo-jira.svg
[2022-07-29T11:19:39] WARNING [django.request.log_response:224] Not Found: /apps/whatsapp/dashboard/assets/img/small-logos/logo-invision.svg
[2022-07-29T11:19:39] WARNING [django.request.log_response:224] Not Found: /apps/whatsapp/dashboard/assets/js/plugins/chartjs.min.js
[2022-07-29T11:19:39] WARNING [django.request.log_response:224] Not Found: /apps/whatsapp/dashboard/assets/js/plugins/perfect-scrollbar.min.js
[2022-07-29T11:19:39] WARNING [django.request.log_response:224] Not Found: /apps/whatsapp/dashboard/assets/img/ivancik.jpg
[2022-07-29T11:19:39] WARNING [django.request.log_response:224] Not Found: /apps/whatsapp/dashboard/assets/img/team-1.jpg
[2022-07-29T11:22:29] INFO [django.utils.autoreload.trigger_reload:251] C:\Users\hp\Desktop\Internship Assignments\billapp\groups\views.py changed, reloading.
[2022-07-29T11:22:29] DEBUG [asyncio.__init__:624] Using proactor: IocpProactor
[2022-07-29T11:26:21] INFO [django.utils.autoreload.trigger_reload:251] C:\Users\hp\Desktop\Internship Assignments\billapp\groups\views.py changed, reloading.
[2022-07-29T11:26:21] DEBUG [asyncio.__init__:624] Using proactor: IocpProactor
[2022-07-29T11:27:17] INFO [django.utils.autoreload.trigger_reload:251] C:\Users\hp\Desktop\Internship Assignments\billapp\plans\views.py changed, reloading.
[2022-07-29T11:27:17] DEBUG [asyncio.__init__:624] Using proactor: IocpProactor
[2022-07-29T11:27:48] INFO [django.utils.autoreload.trigger_reload:251] C:\Users\hp\Desktop\Internship Assignments\billapp\plans\views.py changed, reloading.
[2022-07-29T11:27:48] DEBUG [asyncio.__init__:624] Using proactor: IocpProactor
[2022-07-29T11:29:08] INFO [django.utils.autoreload.trigger_reload:251] C:\Users\hp\Desktop\Internship Assignments\billapp\groups\urls.py changed, reloading.
[2022-07-29T11:29:08] DEBUG [asyncio.__init__:624] Using proactor: IocpProactor
[2022-07-29T11:40:06] INFO [django.utils.autoreload.trigger_reload:251] C:\Users\hp\Desktop\Internship Assignments\billapp\groups\views.py changed, reloading.
[2022-07-29T11:40:06] DEBUG [asyncio.__init__:624] Using proactor: IocpProactor
[2022-07-29T11:40:32] INFO [django.utils.autoreload.trigger_reload:251] C:\Users\hp\Desktop\Internship Assignments\billapp\groups\views.py changed, reloading.
[2022-07-29T11:40:32] DEBUG [asyncio.__init__:624] Using proactor: IocpProactor
[2022-07-29T11:40:41] INFO [django.utils.autoreload.trigger_reload:251] C:\Users\hp\Desktop\Internship Assignments\billapp\groups\views.py changed, reloading.
[2022-07-29T11:40:41] DEBUG [asyncio.__init__:624] Using proactor: IocpProactor
[2022-07-29T11:41:16] ERROR [django.request.log_response:224] Internal Server Error: /groups/group/0gYd2EWazp
Traceback (most recent call last):
  File "C:\Users\hp\AppData\Local\Packages\PythonSoftwareFoundation.Python.3.9_qbz5n2kfra8p0\LocalCache\local-packages\Python39\site-packages\django\core\handlers\exception.py", line 47, in inner
    response = get_response(request)
  File "C:\Users\hp\AppData\Local\Packages\PythonSoftwareFoundation.Python.3.9_qbz5n2kfra8p0\LocalCache\local-packages\Python39\site-packages\django\core\handlers\base.py", line 181, in _get_response
    response = wrapped_callback(request, *callback_args, **callback_kwargs)
  File "C:\Users\hp\Desktop\Internship Assignments\billapp\groups\views.py", line 47, in show_group
    user_ = {'username': i.user.username, 'group': i.group_set.filter(app=group.app).title}
AttributeError: 'QuerySet' object has no attribute 'title'
[2022-07-29T11:41:34] INFO [django.utils.autoreload.trigger_reload:251] C:\Users\hp\Desktop\Internship Assignments\billapp\groups\views.py changed, reloading.
[2022-07-29T11:41:34] DEBUG [asyncio.__init__:624] Using proactor: IocpProactor
[2022-07-29T11:45:21] INFO [django.utils.autoreload.trigger_reload:251] C:\Users\hp\Desktop\Internship Assignments\billapp\groups\views.py changed, reloading.
[2022-07-29T11:45:21] DEBUG [asyncio.__init__:624] Using proactor: IocpProactor
[2022-07-29T11:45:29] INFO [django.utils.autoreload.trigger_reload:251] C:\Users\hp\Desktop\Internship Assignments\billapp\groups\views.py changed, reloading.
[2022-07-29T11:45:29] DEBUG [asyncio.__init__:624] Using proactor: IocpProactor
[2022-07-29T11:46:35] ERROR [django.request.log_response:224] Internal Server Error: /groups/group/0gYd2EWazp
Traceback (most recent call last):
  File "C:\Users\hp\AppData\Local\Packages\PythonSoftwareFoundation.Python.3.9_qbz5n2kfra8p0\LocalCache\local-packages\Python39\site-packages\django\core\handlers\exception.py", line 47, in inner
    response = get_response(request)
  File "C:\Users\hp\AppData\Local\Packages\PythonSoftwareFoundation.Python.3.9_qbz5n2kfra8p0\LocalCache\local-packages\Python39\site-packages\django\core\handlers\base.py", line 181, in _get_response
    response = wrapped_callback(request, *callback_args, **callback_kwargs)
  File "C:\Users\hp\Desktop\Internship Assignments\billapp\groups\views.py", line 87, in show_group
    print(forms.error)
AttributeError: module 'django.forms' has no attribute 'error'
[2022-07-29T11:47:05] INFO [django.utils.autoreload.trigger_reload:251] C:\Users\hp\Desktop\Internship Assignments\billapp\groups\views.py changed, reloading.
[2022-07-29T11:47:05] DEBUG [asyncio.__init__:624] Using proactor: IocpProactor
[2022-07-29T11:47:15] ERROR [django.request.log_response:224] Internal Server Error: /groups/group/0gYd2EWazp
Traceback (most recent call last):
  File "C:\Users\hp\AppData\Local\Packages\PythonSoftwareFoundation.Python.3.9_qbz5n2kfra8p0\LocalCache\local-packages\Python39\site-packages\django\core\handlers\exception.py", line 47, in inner
    response = get_response(request)
  File "C:\Users\hp\AppData\Local\Packages\PythonSoftwareFoundation.Python.3.9_qbz5n2kfra8p0\LocalCache\local-packages\Python39\site-packages\django\core\handlers\base.py", line 181, in _get_response
    response = wrapped_callback(request, *callback_args, **callback_kwargs)
  File "C:\Users\hp\Desktop\Internship Assignments\billapp\groups\views.py", line 62, in show_group
    return render(request, 'groups-panel/group.html', payload)
  File "C:\Users\hp\AppData\Local\Packages\PythonSoftwareFoundation.Python.3.9_qbz5n2kfra8p0\LocalCache\local-packages\Python39\site-packages\django\shortcuts.py", line 19, in render
    content = loader.render_to_string(template_name, context, request, using=using)
  File "C:\Users\hp\AppData\Local\Packages\PythonSoftwareFoundation.Python.3.9_qbz5n2kfra8p0\LocalCache\local-packages\Python39\site-packages\django\template\loader.py", line 62, in render_to_string
    return template.render(context, request)
  File "C:\Users\hp\AppData\Local\Packages\PythonSoftwareFoundation.Python.3.9_qbz5n2kfra8p0\LocalCache\local-packages\Python39\site-packages\django\template\backends\django.py", line 61, in render
    return self.template.render(context)
  File "C:\Users\hp\AppData\Local\Packages\PythonSoftwareFoundation.Python.3.9_qbz5n2kfra8p0\LocalCache\local-packages\Python39\site-packages\django\template\base.py", line 170, in render
    return self._render(context)
  File "C:\Users\hp\AppData\Local\Packages\PythonSoftwareFoundation.Python.3.9_qbz5n2kfra8p0\LocalCache\local-packages\Python39\site-packages\django\template\base.py", line 162, in _render
    return self.nodelist.render(context)
  File "C:\Users\hp\AppData\Local\Packages\PythonSoftwareFoundation.Python.3.9_qbz5n2kfra8p0\LocalCache\local-packages\Python39\site-packages\django\template\base.py", line 938, in render
    bit = node.render_annotated(context)
  File "C:\Users\hp\AppData\Local\Packages\PythonSoftwareFoundation.Python.3.9_qbz5n2kfra8p0\LocalCache\local-packages\Python39\site-packages\django\template\base.py", line 905, in render_annotated
    return self.render(context)
  File "C:\Users\hp\AppData\Local\Packages\PythonSoftwareFoundation.Python.3.9_qbz5n2kfra8p0\LocalCache\local-packages\Python39\site-packages\django\template\loader_tags.py", line 53, in render
    result = self.nodelist.render(context)
  File "C:\Users\hp\AppData\Local\Packages\PythonSoftwareFoundation.Python.3.9_qbz5n2kfra8p0\LocalCache\local-packages\Python39\site-packages\django\template\base.py", line 938, in render
    bit = node.render_annotated(context)
  File "C:\Users\hp\AppData\Local\Packages\PythonSoftwareFoundation.Python.3.9_qbz5n2kfra8p0\LocalCache\local-packages\Python39\site-packages\django\template\base.py", line 905, in render_annotated
    return self.render(context)
  File "C:\Users\hp\AppData\Local\Packages\PythonSoftwareFoundation.Python.3.9_qbz5n2kfra8p0\LocalCache\local-packages\Python39\site-packages\django\template\defaulttags.py", line 446, in render
    url = reverse(view_name, args=args, kwargs=kwargs, current_app=current_app)
  File "C:\Users\hp\AppData\Local\Packages\PythonSoftwareFoundation.Python.3.9_qbz5n2kfra8p0\LocalCache\local-packages\Python39\site-packages\django\urls\base.py", line 86, in reverse
    return resolver._reverse_with_prefix(view, prefix, *args, **kwargs)
  File "C:\Users\hp\AppData\Local\Packages\PythonSoftwareFoundation.Python.3.9_qbz5n2kfra8p0\LocalCache\local-packages\Python39\site-packages\django\urls\resolvers.py", line 694, in _reverse_with_prefix
    raise NoReverseMatch(msg)
django.urls.exceptions.NoReverseMatch: Reverse for 'update-group' with arguments '('0gYd2EWazp',)' not found. 1 pattern(s) tried: ['groups/update\\-user\\-group/(?P<slug>[^/]+)/(?P<groupslug>[^/]+)$']
[2022-07-29T11:49:04] WARNING [django.request.log_response:224] Not Found: /apps/whatsapp/dashboard/assets/js/plugins/perfect-scrollbar.min.js
[2022-07-29T11:49:06] WARNING [django.request.log_response:224] Not Found: /apps/whatsapp/dashboard/assets/css/styles.css
[2022-07-29T11:49:06] WARNING [django.request.log_response:224] Not Found: /apps/whatsapp/dashboard/assets/img/illustrations/rocket-white.png
[2022-07-29T11:49:06] WARNING [django.request.log_response:224] Not Found: /apps/whatsapp/dashboard/assets/img/small-logos/logo-xd.svg
[2022-07-29T11:49:06] WARNING [django.request.log_response:224] Not Found: /apps/whatsapp/dashboard/assets/img/team-1.jpg
[2022-07-29T11:49:06] WARNING [django.request.log_response:224] Not Found: /apps/whatsapp/dashboard/assets/img/team-2.jpg
[2022-07-29T11:49:06] WARNING [django.request.log_response:224] Not Found: /apps/whatsapp/dashboard/assets/img/team-3.jpg
[2022-07-29T11:49:06] WARNING [django.request.log_response:224] Not Found: /apps/whatsapp/dashboard/assets/img/team-4.jpg
[2022-07-29T11:49:06] WARNING [django.request.log_response:224] Not Found: /apps/whatsapp/dashboard/assets/img/small-logos/logo-atlassian.svg
[2022-07-29T11:49:06] WARNING [django.request.log_response:224] Not Found: /apps/whatsapp/dashboard/assets/img/small-logos/logo-slack.svg
[2022-07-29T11:49:06] WARNING [django.request.log_response:224] Not Found: /apps/whatsapp/dashboard/assets/img/small-logos/logo-spotify.svg
[2022-07-29T11:49:06] WARNING [django.request.log_response:224] Not Found: /apps/whatsapp/dashboard/assets/img/small-logos/logo-jira.svg
[2022-07-29T11:49:06] WARNING [django.request.log_response:224] Not Found: /apps/whatsapp/dashboard/assets/img/small-logos/logo-invision.svg
[2022-07-29T11:49:06] WARNING [django.request.log_response:224] Not Found: /apps/whatsapp/dashboard/assets/js/plugins/chartjs.min.js
[2022-07-29T11:49:06] WARNING [django.request.log_response:224] Not Found: /apps/whatsapp/dashboard/assets/js/plugins/perfect-scrollbar.min.js
[2022-07-29T11:49:06] WARNING [django.request.log_response:224] Not Found: /apps/whatsapp/dashboard/assets/css/styles.css
[2022-07-29T11:49:07] WARNING [django.request.log_response:224] Not Found: /apps/whatsapp/dashboard/assets/img/team-2.jpg
[2022-07-29T11:49:07] WARNING [django.request.log_response:224] Not Found: /apps/whatsapp/dashboard/assets/img/team-4.jpg
[2022-07-29T11:49:07] WARNING [django.request.log_response:224] Not Found: /apps/whatsapp/dashboard/assets/img/team-3.jpg
[2022-07-29T11:49:07] WARNING [django.request.log_response:224] Not Found: /apps/whatsapp/dashboard/assets/img/team-1.jpg
[2022-07-29T11:49:07] WARNING [django.request.log_response:224] Not Found: /apps/whatsapp/dashboard/assets/img/ivancik.jpg
[2022-07-29T11:49:51] INFO [django.utils.autoreload.trigger_reload:251] C:\Users\hp\Desktop\Internship Assignments\billapp\plans\urls.py changed, reloading.
[2022-07-29T11:49:51] DEBUG [asyncio.__init__:624] Using proactor: IocpProactor
[2022-07-29T11:50:15] INFO [django.utils.autoreload.trigger_reload:251] C:\Users\hp\Desktop\Internship Assignments\billapp\plans\views.py changed, reloading.
[2022-07-29T11:50:15] DEBUG [asyncio.__init__:624] Using proactor: IocpProactor
[2022-07-29T11:56:10] INFO [django.utils.autoreload.trigger_reload:251] C:\Users\hp\Desktop\Internship Assignments\billapp\accounts\models.py changed, reloading.
[2022-07-29T11:56:10] DEBUG [asyncio.__init__:624] Using proactor: IocpProactor
[2022-07-29T11:56:12] DEBUG [asyncio.__init__:624] Using proactor: IocpProactor
[2022-07-29T11:56:15] DEBUG [asyncio.__init__:624] Using proactor: IocpProactor
[2022-07-29T11:56:19] DEBUG [asyncio.__init__:624] Using proactor: IocpProactor
[2022-09-21T14:14:58] INFO [django.utils.autoreload.trigger_reload:266] C:\Users\10800587\Documents\billapp\accounts\views.py changed, reloading.
[2022-09-21T14:15:01] INFO [django.utils.autoreload.trigger_reload:266] C:\Users\10800587\Documents\billapp\accounts\views.py changed, reloading.
[2022-09-21T14:15:18] WARNING [django.request.log_response:241] Not Found: /favicon.ico
